Workbook

Sheet Summary
A1: Document Organizer v2.1 — Maker-checker test evidence
A2: Generated 23-Oct-2026. Maker = the developer's automated suites (final round 5). Checker = an independent agent that did not write the code or the maker's tests: it re-ran every suite on its own instance and ran its own scenarios.
A4: Suite | B4: Checks | C4: Maker PASS | D4: Maker FAIL | E4: Checker PASS | F4: Checker FAIL / not run
A5: tests/e2e.mjs | B5: =COUNTIF('Test cases'!$B$2:$B$469,"tests/e2e.mjs") -> 159 | C5: =COUNTIFS('Test cases'!$B$2:$B$469,"tests/e2e.mjs",'Test cases'!$E$2:$E$469,"PASS") -> 159 | D5: =COUNTIFS('Test cases'!$B$2:$B$469,"tests/e2e.mjs",'Test cases'!$E$2:$E$469,"FAIL") -> 0 | E5: =COUNTIFS('Test cases'!$B$2:$B$469,"tests/e2e.mjs",'Test cases'!$G$2:$G$469,"PASS") -> 159 | F5: =B5-E5 -> 0
A6: tests/e2e-mapping.mjs | B6: =COUNTIF('Test cases'!$B$2:$B$469,"tests/e2e-mapping.mjs") -> 24 | C6: =COUNTIFS('Test cases'!$B$2:$B$469,"tests/e2e-mapping.mjs",'Test cases'!$E$2:$E$469,"PASS") -> 24 | D6: =COUNTIFS('Test cases'!$B$2:$B$469,"tests/e2e-mapping.mjs",'Test cases'!$E$2:$E$469,"FAIL") -> 0 | E6: =COUNTIFS('Test cases'!$B$2:$B$469,"tests/e2e-mapping.mjs",'Test cases'!$G$2:$G$469,"PASS") -> 24 | F6: =B6-E6 -> 0
A7: tests/e2e-scenarios.mjs | B7: =COUNTIF('Test cases'!$B$2:$B$469,"tests/e2e-scenarios.mjs") -> 90 | C7: =COUNTIFS('Test cases'!$B$2:$B$469,"tests/e2e-scenarios.mjs",'Test cases'!$E$2:$E$469,"PASS") -> 90 | D7: =COUNTIFS('Test cases'!$B$2:$B$469,"tests/e2e-scenarios.mjs",'Test cases'!$E$2:$E$469,"FAIL") -> 0 | E7: =COUNTIFS('Test cases'!$B$2:$B$469,"tests/e2e-scenarios.mjs",'Test cases'!$G$2:$G$469,"PASS") -> 87 | F7: =B7-E7 -> 3
A8: tests/e2e-exclusions.mjs | B8: =COUNTIF('Test cases'!$B$2:$B$469,"tests/e2e-exclusions.mjs") -> 28 | C8: =COUNTIFS('Test cases'!$B$2:$B$469,"tests/e2e-exclusions.mjs",'Test cases'!$E$2:$E$469,"PASS") -> 28 | D8: =COUNTIFS('Test cases'!$B$2:$B$469,"tests/e2e-exclusions.mjs",'Test cases'!$E$2:$E$469,"FAIL") -> 0 | E8: =COUNTIFS('Test cases'!$B$2:$B$469,"tests/e2e-exclusions.mjs",'Test cases'!$G$2:$G$469,"PASS") -> 28 | F8: =B8-E8 -> 0
A9: tests/e2e-makerchecker.mjs | B9: =COUNTIF('Test cases'!$B$2:$B$469,"tests/e2e-makerchecker.mjs") -> 45 | C9: =COUNTIFS('Test cases'!$B$2:$B$469,"tests/e2e-makerchecker.mjs",'Test cases'!$E$2:$E$469,"PASS") -> 45 | D9: =COUNTIFS('Test cases'!$B$2:$B$469,"tests/e2e-makerchecker.mjs",'Test cases'!$E$2:$E$469,"FAIL") -> 0 | E9: =COUNTIFS('Test cases'!$B$2:$B$469,"tests/e2e-makerchecker.mjs",'Test cases'!$G$2:$G$469,"PASS") -> 45 | F9: =B9-E9 -> 0
A10: tests/e2e-security.mjs | B10: =COUNTIF('Test cases'!$B$2:$B$469,"tests/e2e-security.mjs") -> 12 | C10: =COUNTIFS('Test cases'!$B$2:$B$469,"tests/e2e-security.mjs",'Test cases'!$E$2:$E$469,"PASS") -> 12 | D10: =COUNTIFS('Test cases'!$B$2:$B$469,"tests/e2e-security.mjs",'Test cases'!$E$2:$E$469,"FAIL") -> 0 | E10: =COUNTIFS('Test cases'!$B$2:$B$469,"tests/e2e-security.mjs",'Test cases'!$G$2:$G$469,"PASS") -> 12 | F10: =B10-E10 -> 0
A11: tests/e2e-live.mjs | B11: =COUNTIF('Test cases'!$B$2:$B$469,"tests/e2e-live.mjs") -> 56 | C11: =COUNTIFS('Test cases'!$B$2:$B$469,"tests/e2e-live.mjs",'Test cases'!$E$2:$E$469,"PASS") -> 56 | D11: =COUNTIFS('Test cases'!$B$2:$B$469,"tests/e2e-live.mjs",'Test cases'!$E$2:$E$469,"FAIL") -> 0 | E11: =COUNTIFS('Test cases'!$B$2:$B$469,"tests/e2e-live.mjs",'Test cases'!$G$2:$G$469,"PASS") -> 56 | F11: =B11-E11 -> 0
A12: Browser: multiple mapping files | B12: =COUNTIF('Test cases'!$B$2:$B$469,"Browser: multiple mapping files") -> 15 | C12: =COUNTIFS('Test cases'!$B$2:$B$469,"Browser: multiple mapping files",'Test cases'!$E$2:$E$469,"PASS") -> 15 | D12: =COUNTIFS('Test cases'!$B$2:$B$469,"Browser: multiple mapping files",'Test cases'!$E$2:$E$469,"FAIL") -> 0 | E12: =COUNTIFS('Test cases'!$B$2:$B$469,"Browser: multiple mapping files",'Test cases'!$G$2:$G$469,"PASS") -> 0 | F12: =B12-E12 -> 15
A13: Browser: bulk exclusion | B13: =COUNTIF('Test cases'!$B$2:$B$469,"Browser: bulk exclusion") -> 14 | C13: =COUNTIFS('Test cases'!$B$2:$B$469,"Browser: bulk exclusion",'Test cases'!$E$2:$E$469,"PASS") -> 14 | D13: =COUNTIFS('Test cases'!$B$2:$B$469,"Browser: bulk exclusion",'Test cases'!$E$2:$E$469,"FAIL") -> 0 | E13: =COUNTIFS('Test cases'!$B$2:$B$469,"Browser: bulk exclusion",'Test cases'!$G$2:$G$469,"PASS") -> 0 | F13: =B13-E13 -> 14
A14: Browser: maker-checker | B14: =COUNTIF('Test cases'!$B$2:$B$469,"Browser: maker-checker") -> 14 | C14: =COUNTIFS('Test cases'!$B$2:$B$469,"Browser: maker-checker",'Test cases'!$E$2:$E$469,"PASS") -> 14 | D14: =COUNTIFS('Test cases'!$B$2:$B$469,"Browser: maker-checker",'Test cases'!$E$2:$E$469,"FAIL") -> 0 | E14: =COUNTIFS('Test cases'!$B$2:$B$469,"Browser: maker-checker",'Test cases'!$G$2:$G$469,"PASS") -> 0 | F14: =B14-E14 -> 14
A15: Crash and resume (SIGKILL during copy) | B15: =COUNTIF('Test cases'!$B$2:$B$469,"Crash and resume (SIGKILL during copy)") -> 5 | C15: =COUNTIFS('Test cases'!$B$2:$B$469,"Crash and resume (SIGKILL during copy)",'Test cases'!$E$2:$E$469,"PASS") -> 5 | D15: =COUNTIFS('Test cases'!$B$2:$B$469,"Crash and resume (SIGKILL during copy)",'Test cases'!$E$2:$E$469,"FAIL") -> 0 | E15: =COUNTIFS('Test cases'!$B$2:$B$469,"Crash and resume (SIGKILL during copy)",'Test cases'!$G$2:$G$469,"PASS") -> 0 | F15: =B15-E15 -> 5
A16: Upgrade from v2.0 database | B16: =COUNTIF('Test cases'!$B$2:$B$469,"Upgrade from v2.0 database") -> 6 | C16: =COUNTIFS('Test cases'!$B$2:$B$469,"Upgrade from v2.0 database",'Test cases'!$E$2:$E$469,"PASS") -> 6 | D16: =COUNTIFS('Test cases'!$B$2:$B$469,"Upgrade from v2.0 database",'Test cases'!$E$2:$E$469,"FAIL") -> 0 | E16: =COUNTIFS('Test cases'!$B$2:$B$469,"Upgrade from v2.0 database",'Test cases'!$G$2:$G$469,"PASS") -> 0 | F16: =B16-E16 -> 6
A17: Total (maker suites) | B17: =SUM(B5:B16) -> 468 | C17: =SUM(C5:C16) -> 468 | D17: =SUM(D5:D16) -> 0 | E17: =SUM(E5:E16) -> 411 | F17: =SUM(F5:F16) -> 57
A19: Checker's own scenarios (latest run) | B19: =COUNTA('Checker scenarios'!$A$2:$A$296) -> 295 | E19: =COUNTIF('Checker scenarios'!$F$2:$F$296,"PASS") -> 283 | F19: =COUNTIF('Checker scenarios'!$F$2:$F$296,"FAIL") -> 12 | G19: Each FAIL row was reviewed: a problem that is now fixed, or a mistake in the checker's own script (see the Checker's review column).
A20: of which still open after review | B20: =COUNTIF('Checker scenarios'!$I$2:$I$296,"Open") -> 0
A22: Findings | B22: Count | C22: Fixed | D22: Open | E22: High / Medium | F22: Low
A23: Round 1 | B23: =COUNTIF(Findings!$B$2:$B$31,1) -> 15 | C23: =COUNTIFS(Findings!$B$2:$B$31,1,Findings!$I$2:$I$31,"Fixed") -> 15 | D23: =COUNTIFS(Findings!$B$2:$B$31,1,Findings!$I$2:$I$31,"Open") -> 0 | E23: =COUNTIFS(Findings!$B$2:$B$31,1,Findings!$D$2:$D$31,"High")+COUNTIFS(Findings!$B$2:$B$31,1,Findings!$D$2:$D$31,"Medium") -> 7 | F23: =COUNTIFS(Findings!$B$2:$B$31,1,Findings!$D$2:$D$31,"Low") -> 8
A24: Round 2 | B24: =COUNTIF(Findings!$B$2:$B$31,2) -> 7 | C24: =COUNTIFS(Findings!$B$2:$B$31,2,Findings!$I$2:$I$31,"Fixed") -> 7 | D24: =COUNTIFS(Findings!$B$2:$B$31,2,Findings!$I$2:$I$31,"Open") -> 0 | E24: =COUNTIFS(Findings!$B$2:$B$31,2,Findings!$D$2:$D$31,"High")+COUNTIFS(Findings!$B$2:$B$31,2,Findings!$D$2:$D$31,"Medium") -> 4 | F24: =COUNTIFS(Findings!$B$2:$B$31,2,Findings!$D$2:$D$31,"Low") -> 3
A25: Round 3 | B25: =COUNTIF(Findings!$B$2:$B$31,3) -> 7 | C25: =COUNTIFS(Findings!$B$2:$B$31,3,Findings!$I$2:$I$31,"Fixed") -> 7 | D25: =COUNTIFS(Findings!$B$2:$B$31,3,Findings!$I$2:$I$31,"Open") -> 0 | E25: =COUNTIFS(Findings!$B$2:$B$31,3,Findings!$D$2:$D$31,"High")+COUNTIFS(Findings!$B$2:$B$31,3,Findings!$D$2:$D$31,"Medium") -> 4 | F25: =COUNTIFS(Findings!$B$2:$B$31,3,Findings!$D$2:$D$31,"Low") -> 3
A26: Round 4 | B26: =COUNTIF(Findings!$B$2:$B$31,4) -> 1 | C26: =COUNTIFS(Findings!$B$2:$B$31,4,Findings!$I$2:$I$31,"Fixed") -> 1 | D26: =COUNTIFS(Findings!$B$2:$B$31,4,Findings!$I$2:$I$31,"Open") -> 0 | E26: =COUNTIFS(Findings!$B$2:$B$31,4,Findings!$D$2:$D$31,"High")+COUNTIFS(Findings!$B$2:$B$31,4,Findings!$D$2:$D$31,"Medium") -> 0 | F26: =COUNTIFS(Findings!$B$2:$B$31,4,Findings!$D$2:$D$31,"Low") -> 1
A28: How to read: "Not run" in the checker column means the maker added the check after the checker's last run, or it is a maker-only browser/process test; the checker covered those areas with its own scripts (Checker scenarios).

Sheet Test cases
A1: Test ID | B1: Suite | C1: Area | D1: Check (what is verified) | E1: Maker result | F1: Maker round | G1: Checker result | H1: Checker round | I1: Notes
A2: EE-001 | B2: tests/e2e.mjs | C2: Core flow: folders, Azure Blob, S3, cross-provider | D2: admin login | E2: PASS | F2: 5 | G2: PASS | H2: 5
A3: EE-002 | B3: tests/e2e.mjs | C3: Core flow: folders, Azure Blob, S3, cross-provider | D3: CSRF header required | E3: PASS | F3: 5 | G3: PASS | H3: 5
A4: EE-003 | B4: tests/e2e.mjs | C4: Core flow: folders, Azure Blob, S3, cross-provider | D4: job created JOB-20261023-0001 | E4: PASS | F4: 5 | G4: PASS | H4: 5
A5: EE-004 | B5: tests/e2e.mjs | C5: Core flow: folders, Azure Blob, S3, cross-provider | D5: mapping read: 471 rows, headers ID,EmployeeCode,Type,Name,Description,UploadedOn,FileName,ModuleCode,SubModuleCode | E5: PASS | F5: 5 | G5: PASS | H5: 5
A6: EE-005 | B6: tests/e2e.mjs | C6: Core flow: folders, Azure Blob, S3, cross-provider | D6: columns auto-mapped | E6: PASS | F6: 5 | G6: PASS | H6: 5
A7: EE-006 | B7: tests/e2e.mjs | C7: Core flow: folders, Azure Blob, S3, cross-provider | D7: scan finished: Awaiting approval | E7: PASS | F7: 5 | G7: PASS | H7: 5
A8: EE-007 | B8: tests/e2e.mjs | C8: Core flow: folders, Azure Blob, S3, cross-provider | D8: unmapped = 7 | E8: PASS | F8: 5 | G8: PASS | H8: 5
A9: EE-008 | B9: tests/e2e.mjs | C9: Core flow: folders, Azure Blob, S3, cross-provider | D9: missing = 3 | E9: PASS | F9: 5 | G9: PASS | H9: 5
A10: EE-009 | B10: tests/e2e.mjs | C10: Core flow: folders, Azure Blob, S3, cross-provider | D10: ambiguous = 2 | E10: PASS | F10: 5 | G10: PASS | H10: 5
A11: EE-010 | B11: tests/e2e.mjs | C11: Core flow: folders, Azure Blob, S3, cross-provider | D11: invalid = 5 (blank emp, blank type, no date, 0-byte, blank filename) | E11: PASS | F11: 5 | G11: PASS | H11: 5
A12: EE-011 | B12: tests/e2e.mjs | C12: Core flow: folders, Azure Blob, S3, cross-provider | D12: duplicate = 2 (duplicate record + duplicate physical file) | E12: PASS | F12: 5 | G12: PASS | H12: 5
A13: EE-012 | B13: tests/e2e.mjs | C13: Core flow: folders, Azure Blob, S3, cross-provider | D13: every discovered file accounted for | E13: PASS | F13: 5 | G13: PASS | H13: 5
... A238: EES-054 | B238: tests/e2e-scenarios.mjs | C238: Mapping scenarios, multiple files, cloud round trip, keep-all rule | D238: nothing kept from the refused upload | E238: PASS | F238: 5 | G238: PASS | H238: 5
A239: EES-055 | B239: tests/e2e-scenarios.mjs | C239: Mapping scenarios, multiple files, cloud round trip, keep-all rule | D239: no files left on disk from the refused upload | E239: PASS | F239: 5 | G239: Not run | I239: Added after the checker's last suite run, or wording differs
A240: EES-056 | B240: tests/e2e-scenarios.mjs | C240: Mapping scenarios, multiple files, cloud round trip, keep-all rule | D240: file already added is refused, naming the earlier file | E240: PASS | F240: 5 | G240: PASS | H240: 5
A241: EES-057 | B241: tests/e2e-scenarios.mjs | C241: Mapping scenarios, multiple files, cloud round trip, keep-all rule | D241: a batch with a broken workbook is refused | E241: PASS | F241: 5 | G241: PASS | H241: 5
A242: EES-058 | B242: tests/e2e-scenarios.mjs | C242: Mapping scenarios, multiple files, cloud round trip, keep-all rule | D242: the good file of a refused batch is not kept | E242: PASS | F242: 5 | G242: PASS | H242: 5
A243: EES-059 | B243: tests/e2e-scenarios.mjs | C243: Mapping scenarios, multiple files, cloud round trip, keep-all rule | D243: only the one accepted file is on disk (mapping-m1.csv) | E243: PASS | F243: 5 | G243: Not run | I243: Added after the checker's last suite run, or wording differs
A244: EES-060 | B244: tests/e2e-scenarios.mjs | C244: Mapping scenarios, multiple files, cloud round trip, keep-all rule | D244: a second file with the same name is renamed (one (2).csv) | E244: PASS | F244: 5 | G244: PASS | H244: 5
A245: EES-061 | B245: tests/e2e-scenarios.mjs | C245: Mapping scenarios, multiple files, cloud round trip, keep-all rule | D245: a file that is not CSV or Excel is refused | E245: PASS | F245: 5 | G245: PASS | H245: 5
A246: EES-062 | B246: tests/e2e-scenarios.mjs | C246: Mapping scenarios, multiple files, cloud round trip, keep-all rule | D246: an empty mapping file is refused | E246: PASS | F246: 5 | G246: PASS | H246: 5
A247: EES-063 | B247: tests/e2e-scenarios.mjs | C247: Mapping scenarios, multiple files, cloud round trip, keep-all rule | D247: removing an unknown mapping file is refused | E247: PASS | F247: 5 | G247: PASS | H247: 5
A248: EES-064 | B248: tests/e2e-scenarios.mjs | C248: Mapping scenarios, multiple files, cloud round trip, keep-all rule | D248: a refused replacement keeps the current mapping file | E248: PASS | F248: 5 | G248: PASS | H248: 5
A249: EES-065 | B249: tests/e2e-scenarios.mjs | C249: Mapping scenarios, multiple files, cloud round trip, keep-all rule | D249: the current mapping file still scans after a refused replacement | E249: PASS | F249: 5 | G249: PASS | H249: 5
A250: EES-066 | B250: tests/e2e-scenarios.mjs | C250: Mapping scenarios, multiple files, cloud round trip, keep-all rule | D250: replacement accepted, even with content similar to the old file | E250: PASS | F250: 5 | G250: PASS | H250: 5
A251: EES-067 | B251: tests/e2e-scenarios.mjs | C251: Mapping scenarios, multiple files, cloud round trip, keep-all rule | D251: replacement leaves only the new file on disk (mapping-m2.csv) | E251: PASS | F251: 5 | G251: Not run | I251: Added after the checker's last suite run, or wording differs
A252: EES-068 | B252: tests/e2e-scenarios.mjs | C252: Mapping scenarios, multiple files, cloud round trip, keep-all rule | D252: replacing a file with identical content is allowed | E252: PASS | F252: 5 | G252: PASS | H252: 5
A253: EES-069 | B253: tests/e2e-scenarios.mjs | C253: Mapping scenarios, multiple files, cloud round trip, keep-all rule | D253: a viewer cannot add or remove mapping files | E253: PASS | F253: 5 | G253: PASS | H253: 5
A254: EES-070 | B254: tests/e2e-scenarios.mjs | C254: Mapping scenarios, multiple files, cloud round trip, keep-all rule | D254: job still scans normally after the refused uploads | E254: PASS | F254: 5 | G254: PASS | H254: 5
A255: EES-071 | B255: tests/e2e-scenarios.mjs | C255: Mapping scenarios, multiple files, cloud round trip, keep-all rule | D255: data sheet found after a summary sheet, hidden sheet skipped (2 rows) | E255: PASS | F255: 5 | G255: PASS | H255: 5
A256: EES-072 | B256: tests/e2e-scenarios.mjs | C256: Mapping scenarios, multiple files, cloud round trip, keep-all rule | D256: only the data sheet is used ({"READY":2,"PROCESSED":0,"UNMAPPED":1,"MISSING":0,"AMBIGUOUS":0,"DUPLICATE":0,"INVALID":0,"FAILED":0,"EXCLUDED":0}) | E256: PASS | F256: 5 | G256: PASS | H256: 5
A257: EES-073 | B257: tests/e2e-scenarios.mjs | C257: Mapping scenarios, multiple files, cloud round trip, keep-all rule | D257: default rule: flag as ambiguous | E257: PASS | F257: 5 | G257: PASS | H257: 5
A258: EES-074 | B258: tests/e2e-scenarios.mjs | C258: Mapping scenarios, multiple files, cloud round trip, keep-all rule | D258: flag: 2 ambiguous files ({"READY":1,"PROCESSED":0,"UNMAPPED":0,"MISSING":0,"AMBIGUOUS":2,"DUPLICATE":0,"INVALID":0,"FAILED":0,"EXCLUDED":0}) | E258: PASS | F258: 5 | G258: PASS | H258: 5
A259: EES-075 | B259: tests/e2e-scenarios.mjs | C259: Mapping scenarios, multiple files, cloud round trip, keep-all rule | D259: an unknown rule is refused | E259: PASS | F259: 5 | G259: PASS | H259: 5
A260: EES-076 | B260: tests/e2e-scenarios.mjs | C260: Mapping scenarios, multiple files, cloud round trip, keep-all rule | D260: keep all: two records that give the same path keep one copy, the other is DUPLICATE | E260: PASS | F260: 5 | G260: PASS | H260: 5
A261: EES-077 | B261: tests/e2e-scenarios.mjs | C261: Mapping scenarios, multiple files, cloud round trip, keep-all rule | D261: exclusion of one copy is re-applied to that copy only after a new scan | E261: PASS | F261: 5 | G261: PASS | H261: 5
A262: EES-078 | B262: tests/e2e-scenarios.mjs | C262: Mapping scenarios, multiple files, cloud round trip, keep-all rule | D262: keep all: one item per record, files still counted once ({"READY":6,"PROCESSED":0,"UNMAPPED":0,"MISSING":0,"AMBIGUOUS":0,"DUPLICATE":0,"INVALID":0,"FAILED":0,"EXCLUDED":0}, 3 files) | E262: PASS | F262: 5 | G262: PASS | H262: 5
A263: EES-079 | B263: tests/e2e-scenarios.mjs | C263: Mapping scenarios, multiple files, cloud round trip, keep-all rule | D263: each record has its own destination: E1/Offer/2024/amb.pdf | E2/PAN/2023/amb.pdf | E3/Form16/2022/amb.pdf | E263: PASS | F263: 5 | G263: PASS | H263: 5
... A415: EEL-056 | B415: tests/e2e-live.mjs | C415: Live scenarios: unsafe names, changed sources, duplicates, encodings, concurrency, reports | D415: items beyond the per-sheet limit continue on another sheet (Summary, Validation, Validation 2) | E415: PASS | F415: 5 | G415: PASS | H415: 5
...

Sheet Checker scenarios
A1: Checker ID | B1: Area | C1: Scenario | D1: Expected | E1: Actual (latest run) | F1: Result | G1: Script | H1: Checker's review | I1: Final verdict
A2: L01 | B2: Per-job lock | C2: A 60 KB mapping uploaded at 6 KB/s (slow VPN) blocks other changes to the same job | D2: other users not blocked for the whole upload (or a clear busy message) | E2: exclude waited 3 ms (200); GET 7 ms; other job 4 ms; upload 200 | F2: PASS | G2: break2.mjs | I2: PASS
A3: L01b | B3: Per-job lock | C3: Other jobs and reads unaffected by one job's lock | D3: < 1 s | E3: GET 7 ms, other job 4 ms | F3: PASS | G3: break2.mjs | I3: PASS
A4: L02 | B4: Per-job lock | C4: Upload that trickles at 300 B/s (stalled client); another user starts a scan | D4: scan not blocked indefinitely; lock freed when upload aborted | E4: after 8 s scan still waiting=false; after client abort scan returned 200 in 4 ms | F4: PASS | G4: break2.mjs | I4: PASS
A5: L03 | B5: Per-job lock | C5: Lock released after client aborted mid-upload | D5: next request immediate | E5: 200 in 4 ms | F5: PASS | G5: break2.mjs | I5: PASS
A6: L04 | B6: Per-job lock | C6: Request aborted while waiting for the lock | D6: no leaked lock | E6: next request 400 in 3 ms | F6: PASS | G6: break2.mjs | I6: PASS
A7: L05 | B7: Per-job lock | C7: 180 concurrent exclude/restore/GET requests over 6 jobs | D7: all answered, no 500, counts consistent | E7: 269 ms; codes {"200":162,"400":18}; consistent true | F7: PASS | G7: break2.mjs | I7: PASS
A8: V01 | B8: Version | C8: Checker only looks (job, items, report, tree) 8 times | D8: version stable | E8: 0A411D7C5CA59C16 | F8: PASS | G8: break2.mjs | I8: PASS
A9: V02 | B9: Version | C9: Unrelated settings change while checker reviews | D9: version unchanged | E9: 0A411D7C5CA59C16 -> 0A411D7C5CA59C16 | F9: PASS | G9: break2.mjs | I9: PASS
A10: V03 | B10: Version | C10: Withdraw changes version; exclude changes version | D10: all different | E10: 0A411D7C5CA59C16 / 721D515FAB3F4DD7 / 721D515FAB3F4DD7 | F10: FAIL | G10: break2.mjs | H10: Mistake in the checker's script (short note value); version change verified by ver2.mjs | I10: Not a defect
A11: V04 | B11: Version | C11: Exclude X, restore X, exclude Y (same status): different exclusions, same counts | D11: version changes (what was excluded differs) | E11: 721D515FAB3F4DD7 vs 721D515FAB3F4DD7 | F11: FAIL | G11: break2.mjs | H11: Info: the version follows counts; the set of files copied is unchanged | I11: Accepted
A12: V05 | B12: Version | C12: Resolve ambiguous changes version | D12: changes | E12: 721D515FAB3F4DD7 -> 588DA7BC76B16BB2 | F12: PASS | G12: break2.mjs | I12: PASS
A13: V06 | B13: Version | C13: Approve with stale version | D13: 409 | E13: 409 The job has changed since you opened it (it was rescanned, resubmitted or its exceptions changed). R | F13: PASS | G13: break2.mjs | I13: PASS
A14: V07 | B14: Version | C14: Approve with a made-up version | D14: 409 | E14: 409 The job has changed since you opened it (it was rescanned, resubmitted or its exceptions changed). R | F14: PASS | G14: break2.mjs | I14: PASS
A15: V08 | B15: Version | C15: Approve with empty version string (API client) | D15: 400/409 (version required with maker-checker) | E15: 400 Maker-checker is on: send the version of the job you reviewed ("version" from GET /api/jobs/{id}). | F15: PASS | G15: break2.mjs | I15: PASS
A16: V09 | B16: Version | C16: Approve with no version field at all | D16: refused when maker-checker on (otherwise the stale-tab check is optional) | E16: 200 {"started":true} | F16: FAIL | G16: break2.mjs | H16: The checker's helper filled in the version automatically; n3.mjs (no version) refused as required | I16: Not a defect
A17: V10 | B17: Version | C17: Approve with current version | D17: 200 | E17: 409 The job has changed since you opened it (it was rescanned, resubmitted or its exceptions changed). R | F17: FAIL | G17: break2.mjs | H17: Mistake in the checker's script (lower-case version); verified by ver2.mjs V10 | I17: Not a defect
A18: S01 | B18: Settings | C18: Misspelt key {"requireSecondApproval": false} | D18: 400 unknown setting (admin thinks it changed) | E18: 400 Unknown setting: requireSecondApproval.; requireSecondApprover still true | F18: PASS | G18: break2.mjs | I18: PASS
A19: S02 | B19: Settings | C19: null value | D19: 400 | E19: 400 Setting requireSecondApprover has an invalid value. | F19: PASS | G19: break2.mjs | I19: PASS
A20: S03 | B20: Settings | C20: Keys in other case | D20: applied | E20: 200 {"allowOverwrite":false,"maxParallelCopies":9,"jobRetentionDays":365,"auditRetentionDays":2555,"loca; rsa false, par 9 | F20: PASS | G20: break2.mjs | I20: PASS
A21: S04 | B21: Settings | C21: String "true" for a boolean | D21: 400 | E21: 400 Setting requireSecondApprover has an invalid value. | F21: PASS | G21: break2.mjs | I21: PASS
A22: S05 | B22: Settings | C22: maxParallelCopies 1,000,000 | D22: clamped to 64 | E22: 200 {"allowOverwrite":false,"maxParallelCopies":64,"jobRetentionDays":365,"auditRetentionDays":2555,"loc -> 64 | F22: PASS | G22: break2.mjs | I22: PASS
A23: S06 | B23: Settings | C23: Array body | D23: 400 | E23: 400 null | F23: PASS | G23: break2.mjs | I23: PASS
A24: S07 | B24: Settings | C24: Fractional number for an integer | D24: 400 | E24: 400 Setting maxParallelCopies has an invalid value. | F24: PASS | G24: break2.mjs | I24: PASS
A25: S08 | B25: Settings | C25: Operator partial PUT | D25: 403 | E25: 403 null | F25: PASS | G25: break2.mjs | I25: PASS
A26: D01 | B26: Dots rule | C26: Employee name "Pvt. Ltd." (not in template) | D26: READY | E26: READY E1/Offer/HR/2024/p1.pdf | F26: PASS | G26: break2.mjs | I26: PASS
A27: D02 | B27: Dots rule | C27: Employee code "A.B." | D27: READY, folder "A.B" | E27: READY A.B/Offer/HR/2024/p2.pdf | F27: PASS | G27: break2.mjs | I27: PASS
A28: D03 | B28: Dots rule | C28: Type "Sr." | D28: READY, folder "Sr" | E28: READY E3/Sr/HR/2024/p3.pdf | F28: PASS | G28: break2.mjs | I28: PASS
A29: D04 | B29: Dots rule | C29: Type "...Report" | D29: READY | E29: READY E4/...Report/HR/2024/p4.pdf | F29: PASS | G29: break2.mjs | I29: PASS
... A86: EX13 | B86: Exclusions | C86: Viewer excludes | D86: 403 | E86: 403 null | F86: PASS | G86: ex.mjs | I86: PASS
A87: EX03 | B87: Exclusions | C87: Exclude a whole reason group | D87: 0 more excluded (one already) | E87: 200 1 item excluded. | F87: FAIL | G87: ex.mjs | H87: Mistake in the checker's expectation (reviewed by the checker) | I87: Not a defect
A88: EX04 | B88: Exclusions | C88: Exclusions remembered after config change and rescan | D88: 2 excluded | E88: 2 | F88: PASS | G88: ex.mjs | I88: PASS
A89: EX05 | B89: Exclusions | C89: Restore a reason group | D89: UNMAPPED again (2) | E89: 200 2 items restored.; unmapped 2 | F89: PASS | G89: ex.mjs | I89: PASS
A90: EX05b | B90: Exclusions | C90: Restore again when nothing excluded | D90: 400 | E90: 400 None of the chosen items are excluded. | F90: PASS | G90: ex.mjs | I90: PASS
A91: SC04b | B91: Rules | C91: KeepAll: one file, two records | D91: 2 READY items, E5 and E6 folders | E91: READY E5/Offer/2024/shared.pdf (File matches 2 mapping records (R5, R6); kept for each (rule) | READY E6/PAN/2024/shared.pdf (File matches 2 mapping records (R5, R6); kept for each (rule) | F91: PASS | G91: ex.mjs | I91: PASS
A92: EX08 | B92: Exclusions | C92: Exclude while job is Draft (after config change) | D92: 400 | E92: 400 Exceptions can be excluded after a scan, while the job is awaiting approval, paused or completed. | F92: PASS | G92: ex.mjs | I92: PASS
A93: SC04c | B93: Rules | C93: KeepAll copies the shared file twice | D93: E5/... and E6/... exist | E93: E5/Offer/2024/shared.pdf, E6/PAN/2024/shared.pdf | F93: PASS | G93: ex.mjs | I93: PASS
A94: SC17 | B94: Processing | C94: Destination contains no .partial files and nothing outside template | D94: clean | E94: clean | F94: PASS | G94: ex.mjs | I94: PASS
A95: SC18 | B95: Processing | C95: Source untouched after copy | D95: 21 files | E95: 21 | F95: PASS | G95: ex.mjs | I95: PASS
A96: EX14 | B96: Exclusions | C96: Exclude every exception after copy | D96: job becomes Completed | E96: 200 9 items excluded. -> Completed | F96: PASS | G96: ex.mjs | I96: PASS
...

Sheet Findings
A1: Finding | B1: Found in round | C1: Found by | D1: Severity | E1: Problem | F1: Fix | G1: Test added (maker) | H1: Re-verified by checker in round | I1: Status
A2: F01 | B2: 1 | C2: Checker | D2: High | E2: A change sent at the same moment as Submit (mapping upload, rules, scan) could leave a changed job marked as submitted, so the checker approved content they had not reviewed. | F2: Every change to one job is handled one request at a time; any return to Draft or a new scan clears the submission. | G2: e2e-makerchecker: submit racing a mapping upload | H2: 2 | I2: Fixed
A3: F02 | B3: 1 | C3: Checker | D3: Medium | E3: Approving from a page opened before the job changed copied the new content (the page said 1 file, 2 were copied). | F3: Approval carries the version the approver reviewed; a changed job returns 409 "The job has changed since you opened it". "1 files" wording fixed. | G3: e2e-makerchecker: stale approval refused (409) | H3: 2 | I3: Fixed
A4: F03 | B4: 1 | C4: Checker | D4: Medium | E4: A source folder inside the destination folder was accepted, and copies could be written into the source. | F4: Source inside destination is refused (folders and cloud prefixes). | G4: e2e-live L5 | H4: 2 | I4: Fixed
A5: F04 | B5: 1 | C5: Checker | D5: Medium | E5: Approve and reject (or withdraw) of the same change request could both succeed. | F5: A decision claims the request (only if still Pending) before acting. | G5: e2e-makerchecker: approve and reject at the same moment | H5: 2 | I5: Fixed
A6: F05 | B6: 1 | C6: Checker | D6: Low | E6: Two simultaneous approvals recorded two approvals in the audit log. | F6: Per-job lock: the second approval sees the job already copying and is refused before anything is recorded. | G6: e2e-makerchecker: two approvals at once | H6: 2 | I6: Fixed
A7: F06 | B7: 1 | C7: Checker | D7: Low | E7: An employee code or type of only dots (".", "..") silently put files one folder higher. | F7: Such values make the item INVALID with a clear reason. | G7: e2e-live L1 | H7: 2 | I7: Fixed
A8: F07 | B8: 1 | C8: Checker | D8: Low | E8: A second change request for items already in a pending request was accepted. | F8: Refused, naming the pending request. | G8: e2e-makerchecker: duplicate request refused | H8: 2 | I8: Fixed
A9: F08 | B9: 1 | C9: Checker | D9: Low | E9: Saving one setting through the API reset the others (could silently turn maker-checker off). | F9: Only the settings sent are changed. | G9: e2e-security: saving one setting | H9: 2 | I9: Fixed
A10: F09 | B10: 1 | C10: Checker | D10: Low | E10: Search treated % and _ as wildcards, so "exclude all in this view" could cover more than intended. | F10: % and _ are searched for literally. | G10: e2e-live L7 | H10: 2 | I10: Fixed
A11: F10 | B11: 1 | C11: Checker | D11: Low | E11: A session cookie kept working after sign-out or a password change. | F11: Server-side sessions ended by sign-out, password change and password reset. | G11: e2e-security: sessions | H11: 2 | I11: Fixed
A12: F11 | B12: 1 | C12: Checker | D12: Low | E12: Five wrong passwords from anywhere locked any account, including admin. | F12: Lockout per user name and computer (IP address). | G12: e2e-security: lockout | H12: 2 | I12: Fixed
A13: F12 | B13: 1 | C13: Maker | D13: Medium | E13: A crash during a copy left half-written ".partial" files at the destination. | F13: Removed when the copy resumes. | G13: Crash and resume test | H13: 1 | I13: Fixed
... A31: F30 | B31: 4 | C31: Checker | D31: Low | E31: Two jobs writing overlapping S3 destinations at once (prefix p/ with folders vs prefix p/E0/) could still overwrite each other with the integrity check off. | F31: The copy lock is keyed by the final object path, so overlapping destinations share it. | G31: e2e-scenarios D: overlapping S3 destinations | H31: 5 | I31: Fixed
